[2023-08-12T21:10:06.937+0000] {taskinstance.py:1103} INFO - Dependencies all met for dep_context=non-requeueable deps ti=<TaskInstance: emrPipeline.validate_file manual__2023-08-12T21:09:03+00:00 [queued]>
[2023-08-12T21:10:06.948+0000] {taskinstance.py:1103} INFO - Dependencies all met for dep_context=requeueable deps ti=<TaskInstance: emrPipeline.validate_file manual__2023-08-12T21:09:03+00:00 [queued]>
[2023-08-12T21:10:06.949+0000] {taskinstance.py:1308} INFO - Starting attempt 1 of 1
[2023-08-12T21:10:06.965+0000] {taskinstance.py:1327} INFO - Executing <Task(PythonOperator): validate_file> on 2023-08-12 21:09:03+00:00
[2023-08-12T21:10:06.973+0000] {standard_task_runner.py:57} INFO - Started process 19216 to run task
[2023-08-12T21:10:06.981+0000] {standard_task_runner.py:84} INFO - Running: ['***', 'tasks', 'run', 'emrPipeline', 'validate_file', 'manual__2023-08-12T21:09:03+00:00', '--job-id', '338', '--raw', '--subdir', 'DAGS_FOLDER/emr.py', '--cfg-path', '/tmp/tmpruk_l4s7']
[2023-08-12T21:10:06.984+0000] {standard_task_runner.py:85} INFO - Job 338: Subtask validate_file
[2023-08-12T21:10:07.000+0000] {warnings.py:109} WARNING - /home/***/.local/lib/python3.9/site-packages/***/settings.py:195: DeprecationWarning: The sql_alchemy_conn option in [core] has been moved to the sql_alchemy_conn option in [database] - the old setting has been used, but please update your config.
  SQL_ALCHEMY_CONN = conf.get("database", "SQL_ALCHEMY_CONN")

[2023-08-12T21:10:07.063+0000] {task_command.py:410} INFO - Running <TaskInstance: emrPipeline.validate_file manual__2023-08-12T21:09:03+00:00 [running]> on host 484e6be077e8
[2023-08-12T21:10:07.193+0000] {taskinstance.py:1545} INFO - Exporting env vars: AIRFLOW_CTX_DAG_OWNER='***' AIRFLOW_CTX_DAG_ID='emrPipeline' AIRFLOW_CTX_TASK_ID='validate_file' AIRFLOW_CTX_EXECUTION_DATE='2023-08-12T21:09:03+00:00' AIRFLOW_CTX_TRY_NUMBER='1' AIRFLOW_CTX_DAG_RUN_ID='manual__2023-08-12T21:09:03+00:00'
[2023-08-12T21:10:07.195+0000] {logging_mixin.py:150} INFO - Reading the file
[2023-08-12T21:10:07.196+0000] {taskinstance.py:1824} ERROR - Task failed with exception
Traceback (most recent call last):
  File "/home/airflow/.local/lib/python3.9/site-packages/airflow/operators/python.py", line 181, in execute
    return_value = self.execute_callable()
  File "/home/airflow/.local/lib/python3.9/site-packages/airflow/operators/python.py", line 198, in execute_callable
    return self.python_callable(*self.op_args, **self.op_kwargs)
  File "/opt/airflow/dags/emr.py", line 122, in validateFile
    os.environ['AWS_ACCESS_KEY_ID']= {{ conn.aws_connection.login }}
NameError: name 'conn' is not defined
[2023-08-12T21:10:07.207+0000] {taskinstance.py:1345} INFO - Marking task as FAILED. dag_id=emrPipeline, task_id=validate_file, execution_date=20230812T210903, start_date=20230812T211006, end_date=20230812T211007
[2023-08-12T21:10:07.218+0000] {standard_task_runner.py:104} ERROR - Failed to execute job 338 for task validate_file (name 'conn' is not defined; 19216)
[2023-08-12T21:10:07.237+0000] {local_task_job_runner.py:225} INFO - Task exited with return code 1
[2023-08-12T21:10:07.266+0000] {taskinstance.py:2653} INFO - 0 downstream tasks scheduled from follow-on schedule check
