[2023-08-12T21:06:16.301+0000] {taskinstance.py:1103} INFO - Dependencies all met for dep_context=non-requeueable deps ti=<TaskInstance: emrPipeline.validate_file manual__2023-08-12T21:05:44+00:00 [queued]>
[2023-08-12T21:06:16.312+0000] {taskinstance.py:1103} INFO - Dependencies all met for dep_context=requeueable deps ti=<TaskInstance: emrPipeline.validate_file manual__2023-08-12T21:05:44+00:00 [queued]>
[2023-08-12T21:06:16.312+0000] {taskinstance.py:1308} INFO - Starting attempt 1 of 1
[2023-08-12T21:06:16.328+0000] {taskinstance.py:1327} INFO - Executing <Task(PythonOperator): validate_file> on 2023-08-12 21:05:44+00:00
[2023-08-12T21:06:16.336+0000] {standard_task_runner.py:57} INFO - Started process 19104 to run task
[2023-08-12T21:06:16.349+0000] {standard_task_runner.py:84} INFO - Running: ['***', 'tasks', 'run', 'emrPipeline', 'validate_file', 'manual__2023-08-12T21:05:44+00:00', '--job-id', '333', '--raw', '--subdir', 'DAGS_FOLDER/emr.py', '--cfg-path', '/tmp/tmpl38ruzl5']
[2023-08-12T21:06:16.355+0000] {standard_task_runner.py:85} INFO - Job 333: Subtask validate_file
[2023-08-12T21:06:16.369+0000] {warnings.py:109} WARNING - /home/***/.local/lib/python3.9/site-packages/***/settings.py:195: DeprecationWarning: The sql_alchemy_conn option in [core] has been moved to the sql_alchemy_conn option in [database] - the old setting has been used, but please update your config.
  SQL_ALCHEMY_CONN = conf.get("database", "SQL_ALCHEMY_CONN")

[2023-08-12T21:06:16.408+0000] {task_command.py:410} INFO - Running <TaskInstance: emrPipeline.validate_file manual__2023-08-12T21:05:44+00:00 [running]> on host 484e6be077e8
[2023-08-12T21:06:16.497+0000] {taskinstance.py:1545} INFO - Exporting env vars: AIRFLOW_CTX_DAG_OWNER='***' AIRFLOW_CTX_DAG_ID='emrPipeline' AIRFLOW_CTX_TASK_ID='validate_file' AIRFLOW_CTX_EXECUTION_DATE='2023-08-12T21:05:44+00:00' AIRFLOW_CTX_TRY_NUMBER='1' AIRFLOW_CTX_DAG_RUN_ID='manual__2023-08-12T21:05:44+00:00'
[2023-08-12T21:06:16.498+0000] {logging_mixin.py:150} INFO - Reading the file
[2023-08-12T21:06:16.499+0000] {taskinstance.py:1824} ERROR - Task failed with exception
Traceback (most recent call last):
  File "/home/airflow/.local/lib/python3.9/site-packages/airflow/operators/python.py", line 181, in execute
    return_value = self.execute_callable()
  File "/home/airflow/.local/lib/python3.9/site-packages/airflow/operators/python.py", line 198, in execute_callable
    return self.python_callable(*self.op_args, **self.op_kwargs)
  File "/opt/airflow/dags/emr.py", line 122, in validateFile
    os.environ['AWS_ACCESS_KEY_ID']= {{ conn.aws_connection.aws_access_key_id }}
NameError: name 'conn' is not defined
[2023-08-12T21:06:16.507+0000] {taskinstance.py:1345} INFO - Marking task as FAILED. dag_id=emrPipeline, task_id=validate_file, execution_date=20230812T210544, start_date=20230812T210616, end_date=20230812T210616
[2023-08-12T21:06:16.519+0000] {standard_task_runner.py:104} ERROR - Failed to execute job 333 for task validate_file (name 'conn' is not defined; 19104)
[2023-08-12T21:06:16.557+0000] {local_task_job_runner.py:225} INFO - Task exited with return code 1
[2023-08-12T21:06:16.576+0000] {taskinstance.py:2653} INFO - 0 downstream tasks scheduled from follow-on schedule check
