[2023-08-13T11:00:31.615+0000] {warnings.py:109} WARNING - /home/***/.local/lib/python3.9/site-packages/***/utils/sqlalchemy.py:124: DeprecationWarning: The sql_alchemy_conn option in [core] has been moved to the sql_alchemy_conn option in [database] - the old setting has been used, but please update your config.
  return not conf.get("database", "sql_alchemy_conn").startswith("mssql")

[2023-08-13T11:00:31.703+0000] {taskinstance.py:1103} INFO - Dependencies all met for dep_context=non-requeueable deps ti=<TaskInstance: userCase2.renameFile scheduled__2023-08-13T10:00:00+00:00 [queued]>
[2023-08-13T11:00:31.713+0000] {taskinstance.py:1103} INFO - Dependencies all met for dep_context=requeueable deps ti=<TaskInstance: userCase2.renameFile scheduled__2023-08-13T10:00:00+00:00 [queued]>
[2023-08-13T11:00:31.713+0000] {taskinstance.py:1308} INFO - Starting attempt 1 of 1
[2023-08-13T11:00:31.729+0000] {taskinstance.py:1327} INFO - Executing <Task(BashOperator): renameFile> on 2023-08-13 10:00:00+00:00
[2023-08-13T11:00:31.736+0000] {standard_task_runner.py:57} INFO - Started process 315 to run task
[2023-08-13T11:00:31.742+0000] {standard_task_runner.py:84} INFO - Running: ['***', 'tasks', 'run', 'userCase2', 'renameFile', 'scheduled__2023-08-13T10:00:00+00:00', '--job-id', '753', '--raw', '--subdir', 'DAGS_FOLDER/userCase.py', '--cfg-path', '/tmp/tmpeyv2cyag']
[2023-08-13T11:00:31.745+0000] {standard_task_runner.py:85} INFO - Job 753: Subtask renameFile
[2023-08-13T11:00:31.760+0000] {warnings.py:109} WARNING - /home/***/.local/lib/python3.9/site-packages/***/settings.py:195: DeprecationWarning: The sql_alchemy_conn option in [core] has been moved to the sql_alchemy_conn option in [database] - the old setting has been used, but please update your config.
  SQL_ALCHEMY_CONN = conf.get("database", "SQL_ALCHEMY_CONN")

[2023-08-13T11:00:31.800+0000] {task_command.py:410} INFO - Running <TaskInstance: userCase2.renameFile scheduled__2023-08-13T10:00:00+00:00 [running]> on host 484e6be077e8
[2023-08-13T11:00:31.811+0000] {warnings.py:109} WARNING - /home/***/.local/lib/python3.9/site-packages/***/utils/sqlalchemy.py:124: DeprecationWarning: The sql_alchemy_conn option in [core] has been moved to the sql_alchemy_conn option in [database] - the old setting has been used, but please update your config.
  return not conf.get("database", "sql_alchemy_conn").startswith("mssql")

[2023-08-13T11:00:31.890+0000] {taskinstance.py:1545} INFO - Exporting env vars: AIRFLOW_CTX_DAG_OWNER='***' AIRFLOW_CTX_DAG_ID='userCase2' AIRFLOW_CTX_TASK_ID='renameFile' AIRFLOW_CTX_EXECUTION_DATE='2023-08-13T10:00:00+00:00' AIRFLOW_CTX_TRY_NUMBER='1' AIRFLOW_CTX_DAG_RUN_ID='scheduled__2023-08-13T10:00:00+00:00'
[2023-08-13T11:00:31.891+0000] {subprocess.py:63} INFO - Tmp dir root location: /tmp
[2023-08-13T11:00:31.892+0000] {subprocess.py:75} INFO - Running command: ['/bin/bash', '-c', 's3_buckName="myawsbucket19080"\ns3_location="raw/movies.csv"\ns3_file_name_without_ext=${s3_location%.*}\ns3_file_ext=${s3_location: -4}\nexport AWS_ACCESS_KEY_ID=AKIAYJC6EOICLIH36STV\nexport AWS_SECRET_ACCESS_KEY=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\ntimestamp=20230813T100000\naws s3 mv  s3://${s3_buckName}/${s3_location}   s3://${s3_buckName}/${s3_file_name_without_ext}_${timestamp}_validated${s3_file_ext}']
[2023-08-13T11:00:31.905+0000] {subprocess.py:86} INFO - Output:
[2023-08-13T11:00:33.387+0000] {subprocess.py:93} INFO - Completed 466 Bytes/466 Bytes (4.6 KiB/s) with 1 file(s) remainingmove failed: s3://myawsbucket19080/raw/movies.csv to s3://myawsbucket19080/raw/movies_20230813T100000_validated.csv An error occurred (AccessDenied) when calling the DeleteObject operation: Access Denied
[2023-08-13T11:00:33.485+0000] {subprocess.py:97} INFO - Command exited with return code 1
[2023-08-13T11:00:33.497+0000] {taskinstance.py:1824} ERROR - Task failed with exception
Traceback (most recent call last):
  File "/home/airflow/.local/lib/python3.9/site-packages/airflow/operators/bash.py", line 210, in execute
    raise AirflowException(
airflow.exceptions.AirflowException: Bash command failed. The command returned a non-zero exit code 1.
[2023-08-13T11:00:33.503+0000] {taskinstance.py:1345} INFO - Marking task as FAILED. dag_id=userCase2, task_id=renameFile, execution_date=20230813T100000, start_date=20230813T110031, end_date=20230813T110033
[2023-08-13T11:00:33.518+0000] {standard_task_runner.py:104} ERROR - Failed to execute job 753 for task renameFile (Bash command failed. The command returned a non-zero exit code 1.; 315)
[2023-08-13T11:00:33.569+0000] {local_task_job_runner.py:225} INFO - Task exited with return code 1
[2023-08-13T11:00:33.617+0000] {taskinstance.py:2653} INFO - 0 downstream tasks scheduled from follow-on schedule check
