[2023-08-12T20:42:07.279+0000] {taskinstance.py:1103} INFO - Dependencies all met for dep_context=non-requeueable deps ti=<TaskInstance: emrPipeline.validate_file manual__2023-08-12T20:40:54+00:00 [queued]>
[2023-08-12T20:42:07.311+0000] {taskinstance.py:1103} INFO - Dependencies all met for dep_context=requeueable deps ti=<TaskInstance: emrPipeline.validate_file manual__2023-08-12T20:40:54+00:00 [queued]>
[2023-08-12T20:42:07.311+0000] {taskinstance.py:1308} INFO - Starting attempt 1 of 1
[2023-08-12T20:42:07.332+0000] {taskinstance.py:1327} INFO - Executing <Task(PythonOperator): validate_file> on 2023-08-12 20:40:54+00:00
[2023-08-12T20:42:07.344+0000] {standard_task_runner.py:84} INFO - Running: ['***', 'tasks', 'run', 'emrPipeline', 'validate_file', 'manual__2023-08-12T20:40:54+00:00', '--job-id', '303', '--raw', '--subdir', 'DAGS_FOLDER/emr.py', '--cfg-path', '/tmp/tmpvcr1_bl2']
[2023-08-12T20:42:07.348+0000] {standard_task_runner.py:85} INFO - Job 303: Subtask validate_file
[2023-08-12T20:42:07.340+0000] {standard_task_runner.py:57} INFO - Started process 18356 to run task
[2023-08-12T20:42:07.377+0000] {warnings.py:109} WARNING - /home/***/.local/lib/python3.9/site-packages/***/settings.py:195: DeprecationWarning: The sql_alchemy_conn option in [core] has been moved to the sql_alchemy_conn option in [database] - the old setting has been used, but please update your config.
  SQL_ALCHEMY_CONN = conf.get("database", "SQL_ALCHEMY_CONN")

[2023-08-12T20:42:07.457+0000] {task_command.py:410} INFO - Running <TaskInstance: emrPipeline.validate_file manual__2023-08-12T20:40:54+00:00 [running]> on host 484e6be077e8
[2023-08-12T20:42:07.605+0000] {taskinstance.py:1545} INFO - Exporting env vars: AIRFLOW_CTX_DAG_OWNER='***' AIRFLOW_CTX_DAG_ID='emrPipeline' AIRFLOW_CTX_TASK_ID='validate_file' AIRFLOW_CTX_EXECUTION_DATE='2023-08-12T20:40:54+00:00' AIRFLOW_CTX_TRY_NUMBER='1' AIRFLOW_CTX_DAG_RUN_ID='manual__2023-08-12T20:40:54+00:00'
[2023-08-12T20:42:07.607+0000] {logging_mixin.py:150} INFO - Reading the file
[2023-08-12T20:42:07.655+0000] {credentials.py:1123} INFO - Found credentials in environment variables.
[2023-08-12T20:42:07.853+0000] {taskinstance.py:1824} ERROR - Task failed with exception
Traceback (most recent call last):
  File "/home/airflow/.local/lib/python3.9/site-packages/airflow/operators/python.py", line 181, in execute
    return_value = self.execute_callable()
  File "/home/airflow/.local/lib/python3.9/site-packages/airflow/operators/python.py", line 198, in execute_callable
    return self.python_callable(*self.op_args, **self.op_kwargs)
  File "/opt/airflow/dags/emr.py", line 126, in validateFile
    obj = s3.get_object(Bucket="{{ dag_run.conf['s3_bucketName'] }}",Key="{{ dag_run.conf['s3_location'] }}")
  File "/home/airflow/.local/lib/python3.9/site-packages/botocore/client.py", line 530, in _api_call
    return self._make_api_call(operation_name, kwargs)
  File "/home/airflow/.local/lib/python3.9/site-packages/botocore/client.py", line 915, in _make_api_call
    api_params = self._emit_api_params(
  File "/home/airflow/.local/lib/python3.9/site-packages/botocore/client.py", line 1027, in _emit_api_params
    self.meta.events.emit(
  File "/home/airflow/.local/lib/python3.9/site-packages/botocore/hooks.py", line 412, in emit
    return self._emitter.emit(aliased_event_name, **kwargs)
  File "/home/airflow/.local/lib/python3.9/site-packages/botocore/hooks.py", line 256, in emit
    return self._emit(event_name, kwargs)
  File "/home/airflow/.local/lib/python3.9/site-packages/botocore/hooks.py", line 239, in _emit
    response = handler(**kwargs)
  File "/home/airflow/.local/lib/python3.9/site-packages/botocore/handlers.py", line 285, in validate_bucket_name
    raise ParamValidationError(report=error_msg)
botocore.exceptions.ParamValidationError: Parameter validation failed:
Invalid bucket name "{{ dag_run.conf['s3_bucketName'] }}": Bucket name must match the regex "^[a-zA-Z0-9.\-_]{1,255}$" or be an ARN matching the regex "^arn:(aws).*:(s3|s3-object-lambda):[a-z\-0-9]*:[0-9]{12}:accesspoint[/:][a-zA-Z0-9\-.]{1,63}$|^arn:(aws).*:s3-outposts:[a-z\-0-9]+:[0-9]{12}:outpost[/:][a-zA-Z0-9\-]{1,63}[/:]accesspoint[/:][a-zA-Z0-9\-]{1,63}$"
[2023-08-12T20:42:07.871+0000] {taskinstance.py:1345} INFO - Marking task as FAILED. dag_id=emrPipeline, task_id=validate_file, execution_date=20230812T204054, start_date=20230812T204207, end_date=20230812T204207
[2023-08-12T20:42:07.890+0000] {standard_task_runner.py:104} ERROR - Failed to execute job 303 for task validate_file (Parameter validation failed:
Invalid bucket name "{{ dag_run.conf['s3_bucketName'] }}": Bucket name must match the regex "^[a-zA-Z0-9.\-_]{1,255}$" or be an ARN matching the regex "^arn:(aws).*:(s3|s3-object-lambda):[a-z\-0-9]*:[0-9]{12}:accesspoint[/:][a-zA-Z0-9\-.]{1,63}$|^arn:(aws).*:s3-outposts:[a-z\-0-9]+:[0-9]{12}:outpost[/:][a-zA-Z0-9\-]{1,63}[/:]accesspoint[/:][a-zA-Z0-9\-]{1,63}$"; 18356)
[2023-08-12T20:42:07.935+0000] {local_task_job_runner.py:225} INFO - Task exited with return code 1
[2023-08-12T20:42:07.962+0000] {taskinstance.py:2653} INFO - 0 downstream tasks scheduled from follow-on schedule check
