[2023-08-27T12:53:31.445+0000] {warnings.py:109} WARNING - /home/***/.local/lib/python3.9/site-packages/***/utils/sqlalchemy.py:124: DeprecationWarning: The sql_alchemy_conn option in [core] has been moved to the sql_alchemy_conn option in [database] - the old setting has been used, but please update your config.
  return not conf.get("database", "sql_alchemy_conn").startswith("mssql")

[2023-08-27T12:53:31.613+0000] {taskinstance.py:1103} INFO - Dependencies all met for dep_context=non-requeueable deps ti=<TaskInstance: ny_taxi_Pipeline.s3_file_check scheduled__2023-08-27T11:00:00+00:00 [queued]>
[2023-08-27T12:53:31.658+0000] {taskinstance.py:1103} INFO - Dependencies all met for dep_context=requeueable deps ti=<TaskInstance: ny_taxi_Pipeline.s3_file_check scheduled__2023-08-27T11:00:00+00:00 [queued]>
[2023-08-27T12:53:31.665+0000] {taskinstance.py:1308} INFO - Starting attempt 1 of 31
[2023-08-27T12:53:31.705+0000] {taskinstance.py:1327} INFO - Executing <Task(S3KeySensor): s3_file_check> on 2023-08-27 11:00:00+00:00
[2023-08-27T12:53:31.725+0000] {standard_task_runner.py:57} INFO - Started process 2958 to run task
[2023-08-27T12:53:31.759+0000] {standard_task_runner.py:84} INFO - Running: ['***', 'tasks', 'run', 'ny_taxi_Pipeline', 's3_file_check', 'scheduled__2023-08-27T11:00:00+00:00', '--job-id', '1801', '--raw', '--subdir', 'DAGS_FOLDER/ny_taxi_datapipeline.py', '--cfg-path', '/tmp/tmpb10e2g7a']
[2023-08-27T12:53:31.804+0000] {standard_task_runner.py:85} INFO - Job 1801: Subtask s3_file_check
[2023-08-27T12:53:31.891+0000] {warnings.py:109} WARNING - /home/***/.local/lib/python3.9/site-packages/***/settings.py:195: DeprecationWarning: The sql_alchemy_conn option in [core] has been moved to the sql_alchemy_conn option in [database] - the old setting has been used, but please update your config.
  SQL_ALCHEMY_CONN = conf.get("database", "SQL_ALCHEMY_CONN")

[2023-08-27T12:53:32.013+0000] {task_command.py:410} INFO - Running <TaskInstance: ny_taxi_Pipeline.s3_file_check scheduled__2023-08-27T11:00:00+00:00 [running]> on host d4028c5ba2ac
[2023-08-27T12:53:32.036+0000] {warnings.py:109} WARNING - /home/***/.local/lib/python3.9/site-packages/***/utils/sqlalchemy.py:124: DeprecationWarning: The sql_alchemy_conn option in [core] has been moved to the sql_alchemy_conn option in [database] - the old setting has been used, but please update your config.
  return not conf.get("database", "sql_alchemy_conn").startswith("mssql")

[2023-08-27T12:53:32.160+0000] {abstractoperator.py:594} ERROR - Exception rendering Jinja template for task 's3_file_check', field 'bucket_key'. Template: "{{ dag_run.conf['s3_location'] }}"
Traceback (most recent call last):
  File "/home/airflow/.local/lib/python3.9/site-packages/airflow/models/abstractoperator.py", line 586, in _do_render_template_fields
    rendered_content = self.render_template(
  File "/home/airflow/.local/lib/python3.9/site-packages/airflow/template/templater.py", line 156, in render_template
    return self._render(template, context)
  File "/home/airflow/.local/lib/python3.9/site-packages/airflow/models/abstractoperator.py", line 540, in _render
    return super()._render(template, context, dag=dag)
  File "/home/airflow/.local/lib/python3.9/site-packages/airflow/template/templater.py", line 113, in _render
    return render_template_to_string(template, context)
  File "/home/airflow/.local/lib/python3.9/site-packages/airflow/utils/helpers.py", line 288, in render_template_to_string
    return render_template(template, cast(MutableMapping[str, Any], context), native=False)
  File "/home/airflow/.local/lib/python3.9/site-packages/airflow/utils/helpers.py", line 283, in render_template
    return "".join(nodes)
  File "<template>", line 12, in root
  File "/home/airflow/.local/lib/python3.9/site-packages/jinja2/runtime.py", line 852, in _fail_with_undefined_error
    raise self._undefined_exception(self._undefined_message)
jinja2.exceptions.UndefinedError: 'dict object' has no attribute 's3_location'
[2023-08-27T12:53:32.162+0000] {taskinstance.py:1824} ERROR - Task failed with exception
Traceback (most recent call last):
  File "/home/airflow/.local/lib/python3.9/site-packages/airflow/models/taskinstance.py", line 1407, in _run_raw_task
    self._execute_task_with_callbacks(context, test_mode)
  File "/home/airflow/.local/lib/python3.9/site-packages/airflow/models/taskinstance.py", line 1531, in _execute_task_with_callbacks
    task_orig = self.render_templates(context=context)
  File "/home/airflow/.local/lib/python3.9/site-packages/airflow/models/taskinstance.py", line 2179, in render_templates
    original_task.render_template_fields(context)
  File "/home/airflow/.local/lib/python3.9/site-packages/airflow/models/baseoperator.py", line 1254, in render_template_fields
    self._do_render_template_fields(self, self.template_fields, context, jinja_env, set())
  File "/home/airflow/.local/lib/python3.9/site-packages/airflow/utils/session.py", line 76, in wrapper
    return func(*args, session=session, **kwargs)
  File "/home/airflow/.local/lib/python3.9/site-packages/airflow/models/abstractoperator.py", line 586, in _do_render_template_fields
    rendered_content = self.render_template(
  File "/home/airflow/.local/lib/python3.9/site-packages/airflow/template/templater.py", line 156, in render_template
    return self._render(template, context)
  File "/home/airflow/.local/lib/python3.9/site-packages/airflow/models/abstractoperator.py", line 540, in _render
    return super()._render(template, context, dag=dag)
  File "/home/airflow/.local/lib/python3.9/site-packages/airflow/template/templater.py", line 113, in _render
    return render_template_to_string(template, context)
  File "/home/airflow/.local/lib/python3.9/site-packages/airflow/utils/helpers.py", line 288, in render_template_to_string
    return render_template(template, cast(MutableMapping[str, Any], context), native=False)
  File "/home/airflow/.local/lib/python3.9/site-packages/airflow/utils/helpers.py", line 283, in render_template
    return "".join(nodes)
  File "<template>", line 12, in root
  File "/home/airflow/.local/lib/python3.9/site-packages/jinja2/runtime.py", line 852, in _fail_with_undefined_error
    raise self._undefined_exception(self._undefined_message)
jinja2.exceptions.UndefinedError: 'dict object' has no attribute 's3_location'
[2023-08-27T12:53:32.208+0000] {taskinstance.py:1345} INFO - Marking task as UP_FOR_RETRY. dag_id=ny_taxi_Pipeline, task_id=s3_file_check, execution_date=20230827T110000, start_date=20230827T125331, end_date=20230827T125332
[2023-08-27T12:53:32.242+0000] {standard_task_runner.py:104} ERROR - Failed to execute job 1801 for task s3_file_check ('dict object' has no attribute 's3_location'; 2958)
[2023-08-27T12:53:32.281+0000] {local_task_job_runner.py:225} INFO - Task exited with return code 1
[2023-08-27T12:53:32.397+0000] {taskinstance.py:2653} INFO - 0 downstream tasks scheduled from follow-on schedule check
