[2023-08-12T20:49:03.296+0000] {taskinstance.py:1103} INFO - Dependencies all met for dep_context=non-requeueable deps ti=<TaskInstance: emrPipeline.validate_file manual__2023-08-12T20:48:01+00:00 [queued]>
[2023-08-12T20:49:03.339+0000] {taskinstance.py:1103} INFO - Dependencies all met for dep_context=requeueable deps ti=<TaskInstance: emrPipeline.validate_file manual__2023-08-12T20:48:01+00:00 [queued]>
[2023-08-12T20:49:03.339+0000] {taskinstance.py:1308} INFO - Starting attempt 1 of 1
[2023-08-12T20:49:03.401+0000] {taskinstance.py:1327} INFO - Executing <Task(PythonOperator): validate_file> on 2023-08-12 20:48:01+00:00
[2023-08-12T20:49:03.430+0000] {standard_task_runner.py:57} INFO - Started process 18565 to run task
[2023-08-12T20:49:03.458+0000] {standard_task_runner.py:84} INFO - Running: ['***', 'tasks', 'run', 'emrPipeline', 'validate_file', 'manual__2023-08-12T20:48:01+00:00', '--job-id', '311', '--raw', '--subdir', 'DAGS_FOLDER/emr.py', '--cfg-path', '/tmp/tmp8ple_dzr']
[2023-08-12T20:49:03.462+0000] {standard_task_runner.py:85} INFO - Job 311: Subtask validate_file
[2023-08-12T20:49:03.524+0000] {warnings.py:109} WARNING - /home/***/.local/lib/python3.9/site-packages/***/settings.py:195: DeprecationWarning: The sql_alchemy_conn option in [core] has been moved to the sql_alchemy_conn option in [database] - the old setting has been used, but please update your config.
  SQL_ALCHEMY_CONN = conf.get("database", "SQL_ALCHEMY_CONN")

[2023-08-12T20:49:03.726+0000] {task_command.py:410} INFO - Running <TaskInstance: emrPipeline.validate_file manual__2023-08-12T20:48:01+00:00 [running]> on host 484e6be077e8
[2023-08-12T20:49:04.425+0000] {taskinstance.py:1545} INFO - Exporting env vars: AIRFLOW_CTX_DAG_OWNER='***' AIRFLOW_CTX_DAG_ID='emrPipeline' AIRFLOW_CTX_TASK_ID='validate_file' AIRFLOW_CTX_EXECUTION_DATE='2023-08-12T20:48:01+00:00' AIRFLOW_CTX_TRY_NUMBER='1' AIRFLOW_CTX_DAG_RUN_ID='manual__2023-08-12T20:48:01+00:00'
[2023-08-12T20:49:04.468+0000] {logging_mixin.py:150} INFO - Reading the file
[2023-08-12T20:49:04.659+0000] {credentials.py:1123} INFO - Found credentials in environment variables.
[2023-08-12T20:49:05.768+0000] {taskinstance.py:1824} ERROR - Task failed with exception
Traceback (most recent call last):
  File "/home/airflow/.local/lib/python3.9/site-packages/airflow/operators/python.py", line 181, in execute
    return_value = self.execute_callable()
  File "/home/airflow/.local/lib/python3.9/site-packages/airflow/operators/python.py", line 198, in execute_callable
    return self.python_callable(*self.op_args, **self.op_kwargs)
  File "/opt/airflow/dags/emr.py", line 126, in validateFile
    obj = s3.get_object(Bucket=kwargs['s3_bucketName'] ,Key= kwargs['s3_location'] )
  File "/home/airflow/.local/lib/python3.9/site-packages/botocore/client.py", line 530, in _api_call
    return self._make_api_call(operation_name, kwargs)
  File "/home/airflow/.local/lib/python3.9/site-packages/botocore/client.py", line 964, in _make_api_call
    raise error_class(parsed_response, operation_name)
botocore.exceptions.ClientError: An error occurred (InvalidAccessKeyId) when calling the GetObject operation: The AWS Access Key Id you provided does not exist in our records.
[2023-08-12T20:49:05.824+0000] {taskinstance.py:1345} INFO - Marking task as FAILED. dag_id=emrPipeline, task_id=validate_file, execution_date=20230812T204801, start_date=20230812T204903, end_date=20230812T204905
[2023-08-12T20:49:05.961+0000] {standard_task_runner.py:104} ERROR - Failed to execute job 311 for task validate_file (An error occurred (InvalidAccessKeyId) when calling the GetObject operation: The AWS Access Key Id you provided does not exist in our records.; 18565)
[2023-08-12T20:49:06.109+0000] {local_task_job_runner.py:225} INFO - Task exited with return code 1
[2023-08-12T20:49:06.257+0000] {taskinstance.py:2653} INFO - 0 downstream tasks scheduled from follow-on schedule check
